Workbook

Sheet All_User
A1: NO | B1: NAME | C1: 이름 | D1: email | E1: Business Title | F1: BU | G1: ROLE | H1: Lease_List | I1: Old_List | J1: ADD_data | K1: Ipad_List | L1: TeamsNum | M1: Printer | N1: Monitor | O1: BU | P1: 영업자 구분 | R1: 퇴사정보
A2: 1 | B2: Dong Jun Ahn | C2: 안동준 | D2: dj.ahn@stryker.com | E2: Sales Manager, Neurovascular | F2: Sales and Marketing Job Family Group | G2: Direct Sales | H2: {=IFERROR(INDEX(Lease_List!D:D,MATCH(All_User!D2,Lease_List!H:H,0)),"없음")} -> 없음 | I2: 5CG2181LW7 | K2: {=IFERROR(INDEX(Ipad_List!C:C,MATCH(All_User!D2,Ipad_List!J:J,0)),"없음")} -> QWG7C19T9N | L2: {=IFERROR(INDEX(TeamsNumber!B:B,MATCH(All_User!D2,TeamsNumber!D:D,0)),"없음")} -> tel:+82234517682 | M2: {=IFERROR(INDEX(Printer!D:D,MATCH(All_User!D2,Printer!G:G,0)),"없음")} -> 없음 | N2: {=IFERROR(INDEX(Monitor!A:A,MATCH(D2,Monitor!D:D,0)),"없음")} -> 없음 | O2: {=IFERROR(INDEX(sales!D:D,MATCH(D2,sales!C:C,0)),"없음")} -> NV | P2: {=IFERROR(INDEX(sales!E:E,MATCH(D2,sales!C:C,0)),"없음")} -> NV | Q2: {=IFERROR(INDEX(sales!C:C,MATCH(D2,sales!C:C,0)),"list없음")} -> dj.ahn@stryker.com
A3: 2 | B3: Jiyong Ahn | C3: 안지용 | D3: gd.ahn@stryker.com | E3: Senior Mako Product Specialist | F3: Sales and Marketing Job Family Group | G3: Medical Education | H3: {=IFERROR(INDEX(Lease_List!D:D,MATCH(All_User!D3,Lease_List!H:H,0)),"없음")} -> 5CD4232BFL | I3: 없음 | K3: {=IFERROR(INDEX(Ipad_List!C:C,MATCH(All_User!D3,Ipad_List!J:J,0)),"없음")} -> L69V0Q1VT3 | L3: {=IFERROR(INDEX(TeamsNumber!B:B,MATCH(All_User!D3,TeamsNumber!D:D,0)),"없음")} -> tel:+82234517566 | M3: {=IFERROR(INDEX(Printer!D:D,MATCH(All_User!D3,Printer!H:H,0)),"없음")} -> 확인중 | N3: {=IFERROR(INDEX(Monitor!A:A,MATCH(D3,Monitor!D:D,0)),"없음")} -> 없음 | O3: {=IFERROR(INDEX(sales!D:D,MATCH(D3,sales!C:C,0)),"없음")} -> 0 | P3: {=IFERROR(INDEX(sales!E:E,MATCH(D3,sales!C:C,0)),"없음")} -> 0
A4: 3 | B4: Andrew Ahn | C4: 안별 | D4: andrew.ahn@stryker.com | E4: Senior Field Service Engineer Medical | F4: Customer Services Job Family Group | G4: Technical Customer Support | H4: {=IFERROR(INDEX(Lease_List!D:D,MATCH(All_User!D4,Lease_List!H:H,0)),"없음")} -> 5CD5179KJ6 | I4: 04/13/22 | K4: {=IFERROR(INDEX(Ipad_List!C:C,MATCH(All_User!D4,Ipad_List!J:J,0)),"없음")} -> C4RQH3W74V | L4: {=IFERROR(INDEX(TeamsNumber!B:B,MATCH(All_User!D4,TeamsNumber!D:D,0)),"없음")} -> tel:+82234517512 | M4: {=IFERROR(INDEX(Printer!D:D,MATCH(All_User!D4,Printer!H:H,0)),"없음")} -> 없음 | N4: {=IFERROR(INDEX(Monitor!A:A,MATCH(D4,Monitor!D:D,0)),"없음")} -> 없음 | O4: {=IFERROR(INDEX(sales!D:D,MATCH(D4,sales!C:C,0)),"없음")} -> 0 | P4: {=IFERROR(INDEX(sales!E:E,MATCH(D4,sales!C:C,0)),"없음")} -> TS | Q4: {=IFERROR(INDEX(sales!C:C,MATCH(D4,sales!C:C,0)),"list없음")} -> andrew.ahn@stryker.com
A5: 4 | B5: Ryan Ahn | C5: 안성현 | D5: ryan.ahn@stryker.com | E5: Senior Kit Representative | F5: Supply Chain Job Family Group | G5: Materials | H5: {=IFERROR(INDEX(Lease_List!D:D,MATCH(All_User!D5,Lease_List!H:H,0)),"없음")} -> 5CD442C071 | I5: 없음 | K5: {=IFERROR(INDEX(Ipad_List!C:C,MATCH(All_User!D5,Ipad_List!J:J,0)),"없음")} -> 없음 | L5: {=IFERROR(INDEX(TeamsNumber!B:B,MATCH(All_User!D5,TeamsNumber!D:D,0)),"없음")} -> tel:+82234517594 | M5: {=IFERROR(INDEX(Printer!D:D,MATCH(All_User!D5,Printer!H:H,0)),"없음")} -> 없음 | N5: {=IFERROR(INDEX(Monitor!A:A,MATCH(D5,Monitor!D:D,0)),"없음")} -> 없음 | O5: {=IFERROR(INDEX(sales!D:D,MATCH(D5,sales!C:C,0)),"없음")} -> 없음 | P5: {=IFERROR(INDEX(sales!E:E,MATCH(D5,sales!C:C,0)),"없음")} -> 없음
A6: 5 | B6: Hyeran An | C6: 안혜란 | D6: hyeran.an@stryker.com | E6: Customer Service Specialist | F6: Customer Services Job Family Group | G6: Customer Services | H6: {=IFERROR(INDEX(Lease_List!D:D,MATCH(All_User!D6,Lease_List!H:H,0)),"없음")} -> 5CD4145N3N | I6: 없음 | K6: {=IFERROR(INDEX(Ipad_List!C:C,MATCH(All_User!D6,Ipad_List!J:J,0)),"없음")} -> 없음 | L6: {=IFERROR(INDEX(TeamsNumber!B:B,MATCH(All_User!D6,TeamsNumber!D:D,0)),"없음")} -> tel:+82234517662 | M6: {=IFERROR(INDEX(Printer!D:D,MATCH(All_User!D6,Printer!H:H,0)),"없음")} -> 없음 | N6: {=IFERROR(INDEX(Monitor!A:A,MATCH(D6,Monitor!D:D,0)),"없음")} -> 없음 | O6: {=IFERROR(INDEX(sales!D:D,MATCH(D6,sales!C:C,0)),"없음")} -> 없음 | P6: {=IFERROR(INDEX(sales!E:E,MATCH(D6,sales!C:C,0)),"없음")} -> 없음
A7: 6 | B7: Sophie Bae | C7: 배지현 | D7: sophie.bae@stryker.com | E7: Business Operation Specialist, Neurovascular | F7: Sales and Marketing Job Family Group | G7: Sales Operations | H7: {=IFERROR(INDEX(Lease_List!D:D,MATCH(All_User!D7,Lease_List!H:H,0)),"없음")} -> 5CD3469HD0 | I7: 없음 | K7: {=IFERROR(INDEX(Ipad_List!C:C,MATCH(All_User!D7,Ipad_List!J:J,0)),"없음")} -> 없음 | L7: {=IFERROR(INDEX(TeamsNumber!B:B,MATCH(All_User!D7,TeamsNumber!D:D,0)),"없음")} -> tel:+82234517661 | M7: {=IFERROR(INDEX(Printer!D:D,MATCH(All_User!D7,Printer!H:H,0)),"없음")} -> 없음 | N7: {=IFERROR(INDEX(Monitor!A:A,MATCH(D7,Monitor!D:D,0)),"없음")} -> 없음 | O7: {=IFERROR(INDEX(sales!D:D,MATCH(D7,sales!C:C,0)),"없음")} -> 없음 | P7: {=IFERROR(INDEX(sales!E:E,MATCH(D7,sales!C:C,0)),"없음")} -> 없음
A8: 7 | B8: Vincent Bae | C8: 배성빈 | D8: vincent.bae@stryker.com | E8: Associate Mako Product Specialist | F8: Sales and Marketing Job Family Group | G8: Medical Education | H8: {=IFERROR(INDEX(Lease_List!D:D,MATCH(All_User!D8,Lease_List!H:H,0)),"없음")} -> 5CD5062YDY | I8: 없음 | K8: {=IFERROR(INDEX(Ipad_List!C:C,MATCH(All_User!D8,Ipad_List!J:J,0)),"없음")} -> HL7Q0T6MHW | L8: {=IFERROR(INDEX(TeamsNumber!B:B,MATCH(All_User!D8,TeamsNumber!D:D,0)),"없음")} -> 없음 | M8: {=IFERROR(INDEX(Printer!D:D,MATCH(All_User!D8,Printer!H:H,0)),"없음")} -> 없음 | N8: {=IFERROR(INDEX(Monitor!A:A,MATCH(D8,Monitor!D:D,0)),"없음")} -> 없음 | O8: {=IFERROR(INDEX(sales!D:D,MATCH(D8,sales!C:C,0)),"없음")} -> Mako | P8: {=IFERROR(INDEX(sales!E:E,MATCH(D8,sales!C:C,0)),"없음")} -> MPS | Q8: {=IFERROR(INDEX(sales!C:C,MATCH(D8,sales!C:C,0)),"list없음")} -> vincent.bae@stryker.com
A9: 8 | B9: Chloe Baek | C9: 백경남 | D9: chloe.baek@stryker.com | E9: Lead Specialist, Demand Planning, MedSurg | F9: Supply Chain Job Family Group | G9: Supply Planning | H9: {=IFERROR(INDEX(Lease_List!D:D,MATCH(All_User!D9,Lease_List!H:H,0)),"없음")} -> 5CD3469HDN | I9: 없음 | K9: {=IFERROR(INDEX(Ipad_List!C:C,MATCH(All_User!D9,Ipad_List!J:J,0)),"없음")} -> 없음 | L9: {=IFERROR(INDEX(TeamsNumber!B:B,MATCH(All_User!D9,TeamsNumber!D:D,0)),"없음")} -> tel:+82234517519 | M9: {=IFERROR(INDEX(Printer!D:D,MATCH(All_User!D9,Printer!H:H,0)),"없음")} -> 없음 | N9: {=IFERROR(INDEX(Monitor!A:A,MATCH(D9,Monitor!D:D,0)),"없음")} -> 없음 | O9: {=IFERROR(INDEX(sales!D:D,MATCH(D9,sales!C:C,0)),"없음")} -> 없음 | P9: {=IFERROR(INDEX(sales!E:E,MATCH(D9,sales!C:C,0)),"없음")} -> 없음
A10: 10 | B10: Alicia Bang | C10: 방은영 | D10: alicia.bang@stryker.com | E10: Senior RA Specialist | F10: RAQA Job Family Group | G10: Regulatory Affairs | H10: {=IFERROR(INDEX(Lease_List!D:D,MATCH(All_User!D10,Lease_List!H:H,0)),"없음")} -> 5CG53403D0 | I10: 없음 | K10: {=IFERROR(INDEX(Ipad_List!C:C,MATCH(All_User!D10,Ipad_List!J:J,0)),"없음")} -> 없음 | L10: {=IFERROR(INDEX(TeamsNumber!B:B,MATCH(All_User!D10,TeamsNumber!D:D,0)),"없음")} -> tel:+82234517637 | M10: {=IFERROR(INDEX(Printer!D:D,MATCH(All_User!D10,Printer!H:H,0)),"없음")} -> 없음 | N10: {=IFERROR(INDEX(Monitor!A:A,MATCH(D10,Monitor!D:D,0)),"없음")} -> LCD 모니터 | O10: {=IFERROR(INDEX(sales!D:D,MATCH(D10,sales!C:C,0)),"없음")} -> 없음 | P10: {=IFERROR(INDEX(sales!E:E,MATCH(D10,sales!C:C,0)),"없음")} -> 없음
A11: 11 | B11: Bella Bang | C11: 방선희 | D11: bella.bang@stryker.com | E11: Mako Product Specialist | F11: Sales and Marketing Job Family Group | G11: Medical Education | H11: {=IFERROR(INDEX(Lease_List!D:D,MATCH(All_User!D11,Lease_List!H:H,0)),"없음")} -> 5CD5062YF5 | I11: 없음 | K11: {=IFERROR(INDEX(Ipad_List!C:C,MATCH(All_User!D11,Ipad_List!J:J,0)),"없음")} -> QXKLQ74WYW | L11: {=IFERROR(INDEX(TeamsNumber!B:B,MATCH(All_User!D11,TeamsNumber!D:D,0)),"없음")} -> tel:+82234517568 | M11: {=IFERROR(INDEX(Printer!D:D,MATCH(All_User!D11,Printer!H:H,0)),"없음")} -> 없음 | N11: {=IFERROR(INDEX(Monitor!A:A,MATCH(D11,Monitor!D:D,0)),"없음")} -> 없음 | O11: {=IFERROR(INDEX(sales!D:D,MATCH(D11,sales!C:C,0)),"없음")} -> Mako | P11: {=IFERROR(INDEX(sales!E:E,MATCH(D11,sales!C:C,0)),"없음")} -> MPS | Q11: {=IFERROR(INDEX(sales!C:C,MATCH(D11,sales!C:C,0)),"list없음")} -> bella.bang@stryker.com
A12: 12 | B12: Sung Hoon Bang | C12: 방성훈 | D12: sunghoon.bang@stryker.com | E12: Lead Sales Representative | F12: Sales and Marketing Job Family Group | G12: Indirect Sales | H12: {=IFERROR(INDEX(Lease_List!D:D,MATCH(All_User!D12,Lease_List!H:H,0)),"없음")} -> 5CD4305D85 | I12: 없음 | K12: {=IFERROR(INDEX(Ipad_List!C:C,MATCH(All_User!D12,Ipad_List!J:J,0)),"없음")} -> OQ2GGXF3FK | L12: {=IFERROR(INDEX(TeamsNumber!B:B,MATCH(All_User!D12,TeamsNumber!D:D,0)),"없음")} -> tel:+82234517591 | M12: {=IFERROR(INDEX(Printer!D:D,MATCH(All_User!D12,Printer!H:H,0)),"없음")} -> 없음 | N12: {=IFERROR(INDEX(Monitor!A:A,MATCH(D12,Monitor!D:D,0)),"없음")} -> 없음 | O12: {=IFERROR(INDEX(sales!D:D,MATCH(D12,sales!C:C,0)),"없음")} -> Knee | P12: {=IFERROR(INDEX(sales!E:E,MATCH(D12,sales!C:C,0)),"없음")} -> Sales | Q12: {=IFERROR(INDEX(sales!C:C,MATCH(D12,sales!C:C,0)),"list없음")} -> sunghoon.bang@stryker.com
A13: 13 | B13: Jisoo Byeon | C13: 변지수 | D13: jisoo.byeon@stryker.com | E13: Business Operation Coordinator | F13: Sales and Marketing Job Family Group | G13: Sales Support | H13: {=IFERROR(INDEX(Lease_List!D:D,MATCH(All_User!D13,Lease_List!H:H,0)),"없음")} -> 5CD4232BFF | I13: 없음 | K13: {=IFERROR(INDEX(Ipad_List!C:C,MATCH(All_User!D13,Ipad_List!J:J,0)),"없음")} -> 없음 | L13: {=IFERROR(INDEX(TeamsNumber!B:B,MATCH(All_User!D13,TeamsNumber!D:D,0)),"없음")} -> tel:+82234517513 | M13: {=IFERROR(INDEX(Printer!D:D,MATCH(All_User!D13,Printer!H:H,0)),"없음")} -> 없음 | N13: {=IFERROR(INDEX(Monitor!A:A,MATCH(D13,Monitor!D:D,0)),"없음")} -> 없음 | O13: {=IFERROR(INDEX(sales!D:D,MATCH(D13,sales!C:C,0)),"없음")} -> 없음 | P13: {=IFERROR(INDEX(sales!E:E,MATCH(D13,sales!C:C,0)),"없음")} -> 없음
A14: 14 | B14: Jun Seong Byun | C14: 변준성 | D14: junseong.byun@stryker.com | E14: Mako Product Specialist | F14: Sales and Marketing Job Family Group | G14: Medical Education | H14: {=IFERROR(INDEX(Lease_List!D:D,MATCH(All_User!D14,Lease_List!H:H,0)),"없음")} -> 5CD442C074 | I14: 없음 | K14: {=IFERROR(INDEX(Ipad_List!C:C,MATCH(All_User!D14,Ipad_List!J:J,0)),"없음")} -> R34F5XVT2M | L14: {=IFERROR(INDEX(TeamsNumber!B:B,MATCH(All_User!D14,TeamsNumber!D:D,0)),"없음")} -> tel:+82234517659 | M14: {=IFERROR(INDEX(Printer!D:D,MATCH(All_User!D14,Printer!H:H,0)),"없음")} -> 없음 | N14: {=IFERROR(INDEX(Monitor!A:A,MATCH(D14,Monitor!D:D,0)),"없음")} -> 없음 | O14: {=IFERROR(INDEX(sales!D:D,MATCH(D14,sales!C:C,0)),"없음")} -> Mako | P14: {=IFERROR(INDEX(sales!E:E,MATCH(D14,sales!C:C,0)),"없음")} -> MPS | Q14: {=IFERROR(INDEX(sales!C:C,MATCH(D14,sales!C:C,0)),"list없음")} -> junseong.byun@stryker.com
A15: 15 | B15: Bruce Cha | C15: 차철민 | D15: Bruce.Cha@stryker.com | E15: Mako Account Manager | F15: Sales and Marketing Job Family Group | G15: Medical Education | H15: {=IFERROR(INDEX(Lease_List!D:D,MATCH(All_User!D15,Lease_List!H:H,0)),"없음")} -> 5CD3469HD6 | I15: 없음 | K15: {=IFERROR(INDEX(Ipad_List!C:C,MATCH(All_User!D15,Ipad_List!J:J,0)),"없음")} -> LXDC4F97QM | L15: {=IFERROR(INDEX(TeamsNumber!B:B,MATCH(All_User!D15,TeamsNumber!D:D,0)),"없음")} -> tel:+82234517549 | M15: {=IFERROR(INDEX(Printer!D:D,MATCH(All_User!D15,Printer!H:H,0)),"없음")} -> SL-C563W | N15: {=IFERROR(INDEX(Monitor!A:A,MATCH(D15,Monitor!D:D,0)),"없음")} -> 없음 | O15: {=IFERROR(INDEX(sales!D:D,MATCH(D15,sales!C:C,0)),"없음")} -> Mako | P15: {=IFERROR(INDEX(sales!E:E,MATCH(D15,sales!C:C,0)),"없음")} -> Sales | Q15: {=IFERROR(INDEX(sales!C:C,MATCH(D15,sales!C:C,0)),"list없음")} -> Bruce.Cha@stryker.com
A16: 16 | B16: Carl Cha | C16: 차영훈 | D16: carl.cha@stryker.com | E16: Technical Service Engineer | F16: Customer Services Job Family Group | G16: Technical Customer Support | H16: {=IFERROR(INDEX(Lease_List!D:D,MATCH(All_User!D16,Lease_List!H:H,0)),"없음")} -> 없음 | I16: 없음 | J16: 5CD32871LG | K16: {=IFERROR(INDEX(Ipad_List!C:C,MATCH(All_User!D16,Ipad_List!J:J,0)),"없음")} -> Q4VGFW40QV | L16: {=IFERROR(INDEX(TeamsNumber!B:B,MATCH(All_User!D16,TeamsNumber!D:D,0)),"없음")} -> tel:+82234517668 | M16: {=IFERROR(INDEX(Printer!D:D,MATCH(All_User!D16,Printer!G:G,0)),"없음")} -> 없음 | N16: {=IFERROR(INDEX(Monitor!A:A,MATCH(D16,Monitor!D:D,0)),"없음")} -> 없음 | O16: {=IFERROR(INDEX(sales!D:D,MATCH(D16,sales!C:C,0)),"없음")} -> 0 | P16: {=IFERROR(INDEX(sales!E:E,MATCH(D16,sales!C:C,0)),"없음")} -> TS | Q16: {=IFERROR(INDEX(sales!C:C,MATCH(D16,sales!C:C,0)),"list없음")} -> carl.cha@stryker.com
A18: 18 | B18: Willy Chang | C18: 장훈 | D18: Willy.Chang@stryker.com | E18: Mako Account Manager | F18: Sales and Marketing Job Family Group | G18: Medical Education | H18: {=IFERROR(INDEX(Lease_List!D:D,MATCH(All_User!D18,Lease_List!H:H,0)),"없음")} -> 5CD5179KHY | I18: 5CG2181LVJ | K18: {=IFERROR(INDEX(Ipad_List!C:C,MATCH(All_User!D18,Ipad_List!J:J,0)),"없음")} -> Q4VMC2579N | L18: {=IFERROR(INDEX(TeamsNumber!B:B,MATCH(All_User!D18,TeamsNumber!D:D,0)),"없음")} -> tel:+82234517557 | M18: {=IFERROR(INDEX(Printer!D:D,MATCH(All_User!D18,Printer!H:H,0)),"없음")} -> SL-C565FW | N18: {=IFERROR(INDEX(Monitor!A:A,MATCH(D18,Monitor!D:D,0)),"없음")} -> 없음 | O18: {=IFERROR(INDEX(sales!D:D,MATCH(D18,sales!C:C,0)),"없음")} -> Mako | P18: {=IFERROR(INDEX(sales!E:E,MATCH(D18,sales!C:C,0)),"없음")} -> Sales | Q18: {=IFERROR(INDEX(sales!C:C,MATCH(D18,sales!C:C,0)),"list없음")} -> Willy.Chang@stryker.com
A19: 19 | B19: Heesun Cho | C19: 조희선 | D19: heesun.cho@stryker.com | E19: Finance Director, Korea | F19: Finance Job Family Group | G19: Finance | H19: {=IFERROR(INDEX(Lease_List!D:D,MATCH(All_User!D19,Lease_List!H:H,0)),"없음")} -> 5CD442C07H | I19: 없음 | K19: {=IFERROR(INDEX(Ipad_List!C:C,MATCH(All_User!D19,Ipad_List!J:J,0)),"없음")} -> DLXCC0M0KC43 | L19: {=IFERROR(INDEX(TeamsNumber!B:B,MATCH(All_User!D19,TeamsNumber!D:D,0)),"없음")} -> tel:+82234517644 | M19: {=IFERROR(INDEX(Printer!D:D,MATCH(All_User!D19,Printer!H:H,0)),"없음")} -> 없음 | N19: {=IFERROR(INDEX(Monitor!A:A,MATCH(D19,Monitor!D:D,0)),"없음")} -> LCD 모니터 | O19: {=IFERROR(INDEX(sales!D:D,MATCH(D19,sales!C:C,0)),"없음")} -> 없음 | P19: {=IFERROR(INDEX(sales!E:E,MATCH(D19,sales!C:C,0)),"없음")} -> 없음
A20: 20 | B20: Martin Cho | C20: 조명수 | D20: martin.cho@stryker.com | E20: Sales Representative, MedSurg, Korea | F20: Sales and Marketing Job Family Group | G20: Indirect Sales | H20: {=IFERROR(INDEX(Lease_List!D:D,MATCH(All_User!D20,Lease_List!H:H,0)),"없음")} -> 5CD5179KHG | I20: 5CG2181LW1 | K20: {=IFERROR(INDEX(Ipad_List!C:C,MATCH(All_User!D20,Ipad_List!J:J,0)),"없음")} -> L2Q9F70301 | L20: {=IFERROR(INDEX(TeamsNumber!B:B,MATCH(All_User!D20,TeamsNumber!D:D,0)),"없음")} -> tel:+82234517699 | M20: {=IFERROR(INDEX(Printer!D:D,MATCH(All_User!D20,Printer!H:H,0)),"없음")} -> SL-C563W | N20: {=IFERROR(INDEX(Monitor!A:A,MATCH(D20,Monitor!D:D,0)),"없음")} -> 없음 | O20: {=IFERROR(INDEX(sales!D:D,MATCH(D20,sales!C:C,0)),"없음")} -> MedSurg | P20: {=IFERROR(INDEX(sales!E:E,MATCH(D20,sales!C:C,0)),"없음")} -> Sales | Q20: {=IFERROR(INDEX(sales!C:C,MATCH(D20,sales!C:C,0)),"list없음")} -> martin.cho@stryker.com
A21: 21 | B21: Jungshin Cho | C21: 조정신 | D21: jungshin.cho@stryker.com | E21: CS Manager | F21: Customer Services Job Family Group | G21: Customer Services | H21: {=IFERROR(INDEX(Lease_List!D:D,MATCH(All_User!D21,Lease_List!H:H,0)),"없음")} -> 5CD442C07C | I21: 없음 | K21: {=IFERROR(INDEX(Ipad_List!C:C,MATCH(All_User!D21,Ipad_List!J:J,0)),"없음")} -> 없음 | L21: {=IFERROR(INDEX(TeamsNumber!B:B,MATCH(All_User!D21,TeamsNumber!D:D,0)),"없음")} -> tel:+82234517658 | M21: {=IFERROR(INDEX(Printer!D:D,MATCH(All_User!D21,Printer!H:H,0)),"없음")} -> 없음 | N21: {=IFERROR(INDEX(Monitor!A:A,MATCH(D21,Monitor!D:D,0)),"없음")} -> 없음 | O21: {=IFERROR(INDEX(sales!D:D,MATCH(D21,sales!C:C,0)),"없음")} -> 없음 | P21: {=IFERROR(INDEX(sales!E:E,MATCH(D21,sales!C:C,0)),"없음")} -> 없음
A23: 23 | B23: Roy Choi | C23: 최호정 | D23: roy.choi@stryker.com | E23: Senior Mako Product Specialist | F23: Sales and Marketing Job Family Group | G23: Medical Education | H23: {=IFERROR(INDEX(Lease_List!D:D,MATCH(All_User!D23,Lease_List!H:H,0)),"없음")} -> 없음 | I23: 07/25/23 | K23: {=IFERROR(INDEX(Ipad_List!C:C,MATCH(All_User!D23,Ipad_List!J:J,0)),"없음")} -> LD0W924NX3 | L23: {=IFERROR(INDEX(TeamsNumber!B:B,MATCH(All_User!D23,TeamsNumber!D:D,0)),"없음")} -> tel:+82234517567 | M23: {=IFERROR(INDEX(Printer!D:D,MATCH(All_User!D23,Printer!G:G,0)),"없음")} -> 없음 | N23: {=IFERROR(INDEX(Monitor!A:A,MATCH(D23,Monitor!D:D,0)),"없음")} -> 없음 | O23: {=IFERROR(INDEX(sales!D:D,MATCH(D23,sales!C:C,0)),"없음")} -> 0 | P23: {=IFERROR(INDEX(sales!E:E,MATCH(D23,sales!C:C,0)),"없음")} -> 0
A24: 24 | B24: Claire Choi | D24: claire.choi@stryker.com | E24: Mako Product Specialist | F24: Sales and Marketing Job Family Group | G24: Medical Education | H24: {=IFERROR(INDEX(Lease_List!D:D,MATCH(All_User!D24,Lease_List!H:H,0)),"없음")} -> 없음 | I24: 없음 | J24: C6CS1Z2(델?) | K24: {=IFERROR(INDEX(Ipad_List!C:C,MATCH(All_User!D24,Ipad_List!J:J,0)),"없음")} -> CQ0MQK66GM | L24: {=IFERROR(INDEX(TeamsNumber!B:B,MATCH(All_User!D24,TeamsNumber!D:D,0)),"없음")} -> tel:+82234517525 | M24: {=IFERROR(INDEX(Printer!D:D,MATCH(All_User!D24,Printer!G:G,0)),"없음")} -> 없음 | N24: {=IFERROR(INDEX(Monitor!A:A,MATCH(D24,Monitor!D:D,0)),"없음")} -> 없음 | O24: {=IFERROR(INDEX(sales!D:D,MATCH(D24,sales!C:C,0)),"없음")} -> Mako | P24: {=IFERROR(INDEX(sales!E:E,MATCH(D24,sales!C:C,0)),"없음")} -> MPS | Q24: {=IFERROR(INDEX(sales!C:C,MATCH(D24,sales!C:C,0)),"list없음")} -> claire.choi@stryker.com
A25: 25 | B25: Brad Choi | C25: 최동혁 | D25: brad.choi@stryker.com | E25: Senior Sales Representative | F25: Sales and Marketing Job Family Group | G25: Indirect Sales | H25: {=IFERROR(INDEX(Lease_List!D:D,MATCH(All_User!D25,Lease_List!H:H,0)),"없음")} -> 5CD4145N3V | I25: 없음 | K25: {=IFERROR(INDEX(Ipad_List!C:C,MATCH(All_User!D25,Ipad_List!J:J,0)),"없음")} -> MKTFHJRWT2 | L25: {=IFERROR(INDEX(TeamsNumber!B:B,MATCH(All_User!D25,TeamsNumber!D:D,0)),"없음")} -> tel:+82234517559 | M25: {=IFERROR(INDEX(Printer!D:D,MATCH(All_User!D25,Printer!H:H,0)),"없음")} -> SL-C563W | N25: {=IFERROR(INDEX(Monitor!A:A,MATCH(D25,Monitor!D:D,0)),"없음")} -> 없음 | O25: {=IFERROR(INDEX(sales!D:D,MATCH(D25,sales!C:C,0)),"없음")} -> Implants | P25: {=IFERROR(INDEX(sales!E:E,MATCH(D25,sales!C:C,0)),"없음")} -> Sales | Q25: {=IFERROR(INDEX(sales!C:C,MATCH(D25,sales!C:C,0)),"list없음")} -> brad.choi@stryker.com
A26: 26 | B26: Kyu Choi | C26: 최규범 | D26: kyu.choi@stryker.com | E26: Sales Representative, NV | F26: Sales and Marketing Job Family Group | G26: Direct Sales | H26: {=IFERROR(INDEX(Lease_List!D:D,MATCH(All_User!D26,Lease_List!H:H,0)),"없음")} -> 5CD5179KHS | I26: 07/25/23 | K26: {=IFERROR(INDEX(Ipad_List!C:C,MATCH(All_User!D26,Ipad_List!J:J,0)),"없음")} -> HP6F2M6GJ7 | L26: {=IFERROR(INDEX(TeamsNumber!B:B,MATCH(All_User!D26,TeamsNumber!D:D,0)),"없음")} -> tel:+82234517623 | M26: {=IFERROR(INDEX(Printer!D:D,MATCH(All_User!D26,Printer!H:H,0)),"없음")} -> SL-C565FW | N26: {=IFERROR(INDEX(Monitor!A:A,MATCH(D26,Monitor!D:D,0)),"없음")} -> 없음 | O26: {=IFERROR(INDEX(sales!D:D,MATCH(D26,sales!C:C,0)),"없음")} -> NV | P26: {=IFERROR(INDEX(sales!E:E,MATCH(D26,sales!C:C,0)),"없음")} -> NV | Q26: {=IFERROR(INDEX(sales!C:C,MATCH(D26,sales!C:C,0)),"list없음")} -> kyu.choi@stryker.com
A28: 28 | B28: Mason Choi | C28: 최민우 | D28: mason.choi@stryker.com | E28: Associate Mako Product Specialist | F28: Sales and Marketing Job Family Group | G28: Medical Education | H28: {=IFERROR(INDEX(Lease_List!D:D,MATCH(All_User!D28,Lease_List!H:H,0)),"없음")} -> 5CD5062YF4 | I28: 없음 | K28: {=IFERROR(INDEX(Ipad_List!C:C,MATCH(All_User!D28,Ipad_List!J:J,0)),"없음")} -> QC36D93T16 | L28: {=IFERROR(INDEX(TeamsNumber!B:B,MATCH(All_User!D28,TeamsNumber!D:D,0)),"없음")} -> tel:+82234517517 | M28: {=IFERROR(INDEX(Printer!D:D,MATCH(All_User!D28,Printer!H:H,0)),"없음")} -> 없음 | N28: {=IFERROR(INDEX(Monitor!A:A,MATCH(D28,Monitor!D:D,0)),"없음")} -> 없음 | O28: {=IFERROR(INDEX(sales!D:D,MATCH(D28,sales!C:C,0)),"없음")} -> Mako | P28: {=IFERROR(INDEX(sales!E:E,MATCH(D28,sales!C:C,0)),"없음")} -> MPS | Q28: {=IFERROR(INDEX(sales!C:C,MATCH(D28,sales!C:C,0)),"list없음")} -> mason.choi@stryker.com
A29: 29 | B29: Jaewook Chung | C29: 정재욱 | D29: jae.chung@stryker.com | E29: Senior Product Manager | F29: Sales and Marketing Job Family Group | G29: Product Management | H29: {=IFERROR(INDEX(Lease_List!D:D,MATCH(All_User!D29,Lease_List!H:H,0)),"없음")} -> 5CD442C072 | I29: 없음 | K29: {=IFERROR(INDEX(Ipad_List!C:C,MATCH(All_User!D29,Ipad_List!J:J,0)),"없음")} -> GMF3VLXNKG | L29: {=IFERROR(INDEX(TeamsNumber!B:B,MATCH(All_User!D29,TeamsNumber!D:D,0)),"없음")} -> tel:+82234517618 | M29: {=IFERROR(INDEX(Printer!D:D,MATCH(All_User!D29,Printer!H:H,0)),"없음")} -> SL-C483W | N29: {=IFERROR(INDEX(Monitor!A:A,MATCH(D29,Monitor!D:D,0)),"없음")} -> LCD 모니터 | O29: {=IFERROR(INDEX(sales!D:D,MATCH(D29,sales!C:C,0)),"없음")} -> 0 | P29: {=IFERROR(INDEX(sales!E:E,MATCH(D29,sales!C:C,0)),"없음")} -> MKT | Q29: {=IFERROR(INDEX(sales!C:C,MATCH(D29,sales!C:C,0)),"list없음")} -> jae.chung@stryker.com
A30: 30 | B30: David Chung | C30: 정석우 | D30: david.chung@stryker.com | E30: Sales Representative | F30: Sales and Marketing Job Family Group | G30: Indirect Sales | H30: {=IFERROR(INDEX(Lease_List!D:D,MATCH(All_User!D30,Lease_List!H:H,0)),"없음")} -> 5CD4232BF1 | I30: 없음 | K30: {=IFERROR(INDEX(Ipad_List!C:C,MATCH(All_User!D30,Ipad_List!J:J,0)),"없음")} -> DWJX4VVTX2 | L30: {=IFERROR(INDEX(TeamsNumber!B:B,MATCH(All_User!D30,TeamsNumber!D:D,0)),"없음")} -> tel:+82234517648 | M30: {=IFERROR(INDEX(Printer!D:D,MATCH(All_User!D30,Printer!H:H,0)),"없음")} -> 없음 | N30: {=IFERROR(INDEX(Monitor!A:A,MATCH(D30,Monitor!D:D,0)),"없음")} -> 없음 | O30: {=IFERROR(INDEX(sales!D:D,MATCH(D30,sales!C:C,0)),"없음")} -> Knee | P30: {=IFERROR(INDEX(sales!E:E,MATCH(D30,sales!C:C,0)),"없음")} -> Sales | Q30: {=IFERROR(INDEX(sales!C:C,MATCH(D30,sales!C:C,0)),"list없음")} -> david.chung@stryker.com
A31: 31 | B31: Chaeyeon Chung | C31: 정채연 | D31: chaeyeon.chung@stryker.com | E31: RA Specialist | F31: RAQA Job Family Group | G31: Regulatory Affairs | H31: {=IFERROR(INDEX(Lease_List!D:D,MATCH(All_User!D31,Lease_List!H:H,0)),"없음")} -> 5CD5062YDT | I31: 없음 | K31: {=IFERROR(INDEX(Ipad_List!C:C,MATCH(All_User!D31,Ipad_List!J:J,0)),"없음")} -> 없음 | L31: {=IFERROR(INDEX(TeamsNumber!B:B,MATCH(All_User!D31,TeamsNumber!D:D,0)),"없음")} -> 없음 | M31: {=IFERROR(INDEX(Printer!D:D,MATCH(All_User!D31,Printer!H:H,0)),"없음")} -> 없음 | N31: {=IFERROR(INDEX(Monitor!A:A,MATCH(D31,Monitor!D:D,0)),"없음")} -> 없음 | O31: {=IFERROR(INDEX(sales!D:D,MATCH(D31,sales!C:C,0)),"없음")} -> 없음 | P31: {=IFERROR(INDEX(sales!E:E,MATCH(D31,sales!C:C,0)),"없음")} -> 없음
A32: 32 | B32: Nathan Eom | C32: 엄태영 | D32: Nathan.Eom@stryker.com | E32: Sales Manager | F32: Sales and Marketing Job Family Group | G32: Indirect Sales | H32: {=IFERROR(INDEX(Lease_List!D:D,MATCH(All_User!D32,Lease_List!H:H,0)),"없음")} -> 5CD4305D8C | I32: 없음 | K32: {=IFERROR(INDEX(Ipad_List!C:C,MATCH(All_User!D32,Ipad_List!J:J,0)),"없음")} -> GW245H3KYL | L32: {=IFERROR(INDEX(TeamsNumber!B:B,MATCH(All_User!D32,TeamsNumber!D:D,0)),"없음")} -> tel:+82234517611 | M32: {=IFERROR(INDEX(Printer!D:D,MATCH(All_User!D32,Printer!H:H,0)),"없음")} -> SL-C486FW | N32: {=IFERROR(INDEX(Monitor!A:A,MATCH(D32,Monitor!D:D,0)),"없음")} -> 없음 | O32: {=IFERROR(INDEX(sales!D:D,MATCH(D32,sales!C:C,0)),"없음")} -> MedSurg | P32: {=IFERROR(INDEX(sales!E:E,MATCH(D32,sales!C:C,0)),"없음")} -> Sales | Q32: {=IFERROR(INDEX(sales!C:C,MATCH(D32,sales!C:C,0)),"list없음")} -> Nathan.Eom@stryker.com
A33: 33 | B33: Jack Eum | C33: 엄재원 | D33: jack.eum@stryker.com | E33: Senior Sales Representative | F33: Sales and Marketing Job Family Group | G33: Indirect Sales | H33: {=IFERROR(INDEX(Lease_List!D:D,MATCH(All_User!D33,Lease_List!H:H,0)),"없음")} -> 없음 | I33: 5CG2261LCR | K33: {=IFERROR(INDEX(Ipad_List!C:C,MATCH(All_User!D33,Ipad_List!J:J,0)),"없음")} -> D64QK42W36 | L33: {=IFERROR(INDEX(TeamsNumber!B:B,MATCH(All_User!D33,TeamsNumber!D:D,0)),"없음")} -> tel:+82234517610 | M33: {=IFERROR(INDEX(Printer!D:D,MATCH(All_User!D33,Printer!G:G,0)),"없음")} -> 없음 | N33: {=IFERROR(INDEX(Monitor!A:A,MATCH(D33,Monitor!D:D,0)),"없음")} -> 없음 | O33: {=IFERROR(INDEX(sales!D:D,MATCH(D33,sales!C:C,0)),"없음")} -> Knee | P33: {=IFERROR(INDEX(sales!E:E,MATCH(D33,sales!C:C,0)),"없음")} -> Sales | Q33: {=IFERROR(INDEX(sales!C:C,MATCH(D33,sales!C:C,0)),"list없음")} -> jack.eum@stryker.com
A34: 34 | B34: Emma Eun | C34: 은예석 | D34: emma.eun@stryker.com | E34: Business Operation Coordinator | F34: Sales and Marketing Job Family Group | G34: Sales Support | H34: {=IFERROR(INDEX(Lease_List!D:D,MATCH(All_User!D34,Lease_List!H:H,0)),"없음")} -> 없음 | I34: 07/25/23 | K34: {=IFERROR(INDEX(Ipad_List!C:C,MATCH(All_User!D34,Ipad_List!J:J,0)),"없음")} -> 없음 | L34: {=IFERROR(INDEX(TeamsNumber!B:B,MATCH(All_User!D34,TeamsNumber!D:D,0)),"없음")} -> 없음 | M34: {=IFERROR(INDEX(Printer!D:D,MATCH(All_User!D34,Printer!G:G,0)),"없음")} -> 없음 | N34: {=IFERROR(INDEX(Monitor!A:A,MATCH(D34,Monitor!D:D,0)),"없음")} -> 없음 | O34: {=IFERROR(INDEX(sales!D:D,MATCH(D34,sales!C:C,0)),"없음")} -> 없음 | P34: {=IFERROR(INDEX(sales!E:E,MATCH(D34,sales!C:C,0)),"없음")} -> 없음
A35: 35 | B35: Gyolim Gu | C35: 구교림 | D35: gyolim.gu@stryker.com | E35: Senior Planner | F35: Supply Chain Job Family Group | G35: Supply Planning | H35: {=IFERROR(INDEX(Lease_List!D:D,MATCH(All_User!D35,Lease_List!H:H,0)),"없음")} -> 5CD442C076 | I35: 5CG2181LVR | K35: {=IFERROR(INDEX(Ipad_List!C:C,MATCH(All_User!D35,Ipad_List!J:J,0)),"없음")} -> 없음 | L35: {=IFERROR(INDEX(TeamsNumber!B:B,MATCH(All_User!D35,TeamsNumber!D:D,0)),"없음")} -> tel:+82234517600 | M35: {=IFERROR(INDEX(Printer!D:D,MATCH(All_User!D35,Printer!H:H,0)),"없음")} -> 없음 | N35: {=IFERROR(INDEX(Monitor!A:A,MATCH(D35,Monitor!D:D,0)),"없음")} -> 없음 | O35: {=IFERROR(INDEX(sales!D:D,MATCH(D35,sales!C:C,0)),"없음")} -> 없음 | P35: {=IFERROR(INDEX(sales!E:E,MATCH(D35,sales!C:C,0)),"없음")} -> 없음
A36: 36 | B36: Alice Han | C36: 한민주 | D36: alice.han@stryker.com | E36: Senior RA Specialist | F36: RAQA Job Family Group | G36: Regulatory Affairs | H36: {=IFERROR(INDEX(Lease_List!D:D,MATCH(All_User!D36,Lease_List!H:H,0)),"없음")} -> 5CD5179KHR | I36: 5CG2181LXB | K36: {=IFERROR(INDEX(Ipad_List!C:C,MATCH(All_User!D36,Ipad_List!J:J,0)),"없음")} -> 없음 | L36: {=IFERROR(INDEX(TeamsNumber!B:B,MATCH(All_User!D36,TeamsNumber!D:D,0)),"없음")} -> tel:+82234517639 | M36: {=IFERROR(INDEX(Printer!D:D,MATCH(All_User!D36,Printer!H:H,0)),"없음")} -> 없음 | N36: {=IFERROR(INDEX(Monitor!A:A,MATCH(D36,Monitor!D:D,0)),"없음")} -> LCD 모니터 | O36: {=IFERROR(INDEX(sales!D:D,MATCH(D36,sales!C:C,0)),"없음")} -> 없음 | P36: {=IFERROR(INDEX(sales!E:E,MATCH(D36,sales!C:C,0)),"없음")} -> 없음
A37: 37 | B37: Leo Han | C37: 한현준 | D37: leo.han@stryker.com | E37: Mako Product Specialist | F37: Sales and Marketing Job Family Group | G37: Medical Education | H37: {=IFERROR(INDEX(Lease_List!D:D,MATCH(All_User!D37,Lease_List!H:H,0)),"없음")} -> 5CD4305D8Y | I37: 없음 | K37: {=IFERROR(INDEX(Ipad_List!C:C,MATCH(All_User!D37,Ipad_List!J:J,0)),"없음")} -> CXVPVQXG09 | L37: {=IFERROR(INDEX(TeamsNumber!B:B,MATCH(All_User!D37,TeamsNumber!D:D,0)),"없음")} -> tel:+82234517588 | M37: {=IFERROR(INDEX(Printer!D:D,MATCH(All_User!D37,Printer!H:H,0)),"없음")} -> SL-C563W | N37: {=IFERROR(INDEX(Monitor!A:A,MATCH(D37,Monitor!D:D,0)),"없음")} -> 없음 | O37: {=IFERROR(INDEX(sales!D:D,MATCH(D37,sales!C:C,0)),"없음")} -> Mako | P37: {=IFERROR(INDEX(sales!E:E,MATCH(D37,sales!C:C,0)),"없음")} -> MPS | Q37: {=IFERROR(INDEX(sales!C:C,MATCH(D37,sales!C:C,0)),"list없음")} -> leo.han@stryker.com
A38: 38 | B38: Mihee Han | C38: 한미희 | D38: mihee.han@stryker.com | E38: Associate Manager, FICM | F38: Finance Job Family Group | G38: Finance | H38: {=IFERROR(INDEX(Lease_List!D:D,MATCH(All_User!D38,Lease_List!H:H,0)),"없음")} -> 5CD3469HDB | I38: 없음 | J38: 5CG10801FQ(retired) | K38: {=IFERROR(INDEX(Ipad_List!C:C,MATCH(All_User!D38,Ipad_List!J:J,0)),"없음")} -> 없음 | L38: {=IFERROR(INDEX(TeamsNumber!B:B,MATCH(All_User!D38,TeamsNumber!D:D,0)),"없음")} -> tel:+82234517546 | M38: {=IFERROR(INDEX(Printer!D:D,MATCH(All_User!D38,Printer!G:G,0)),"없음")} -> 없음 | N38: {=IFERROR(INDEX(Monitor!A:A,MATCH(D38,Monitor!D:D,0)),"없음")} -> 없음 | O38: {=IFERROR(INDEX(sales!D:D,MATCH(D38,sales!C:C,0)),"없음")} -> 없음 | P38: {=IFERROR(INDEX(sales!E:E,MATCH(D38,sales!C:C,0)),"없음")} -> 없음
A39: 39 | B39: Jason Han | C39: 한준석 | D39: jason.han@stryker.com | E39: BU Director, Knee, Korea | F39: Sales and Marketing Job Family Group | G39: Sales and Marketing | H39: {=IFERROR(INDEX(Lease_List!D:D,MATCH(All_User!D39,Lease_List!H:H,0)),"없음")} -> 5CD5179KGZ | I39: 5CG2181LWF | K39: {=IFERROR(INDEX(Ipad_List!C:C,MATCH(All_User!D39,Ipad_List!J:J,0)),"없음")} -> KG27H3Q1J1 | L39: {=IFERROR(INDEX(TeamsNumber!B:B,MATCH(All_User!D39,TeamsNumber!D:D,0)),"없음")} -> tel:+82234517516 | M39: {=IFERROR(INDEX(Printer!D:D,MATCH(All_User!D39,Printer!H:H,0)),"없음")} -> 없음 | N39: {=IFERROR(INDEX(Monitor!A:A,MATCH(D39,Monitor!D:D,0)),"없음")} -> 없음 | O39: {=IFERROR(INDEX(sales!D:D,MATCH(D39,sales!C:C,0)),"없음")} -> 없음 | P39: {=IFERROR(INDEX(sales!E:E,MATCH(D39,sales!C:C,0)),"없음")} -> 없음
A41: 41 | B41: Arum Han | C41: 한아름 | D41: arum.han@stryker.com | E41: QA Manager | F41: RAQA Job Family Group | G41: Quality | H41: {=IFERROR(INDEX(Lease_List!D:D,MATCH(All_User!D41,Lease_List!H:H,0)),"없음")} -> 5CD4305D95 | I41: 없음 | K41: {=IFERROR(INDEX(Ipad_List!C:C,MATCH(All_User!D41,Ipad_List!J:J,0)),"없음")} -> 없음 | L41: {=IFERROR(INDEX(TeamsNumber!B:B,MATCH(All_User!D41,TeamsNumber!D:D,0)),"없음")} -> tel:+82234517634 | M41: {=IFERROR(INDEX(Printer!D:D,MATCH(All_User!D41,Printer!H:H,0)),"없음")} -> 없음 | N41: {=IFERROR(INDEX(Monitor!A:A,MATCH(D41,Monitor!D:D,0)),"없음")} -> 없음 | O41: {=IFERROR(INDEX(sales!D:D,MATCH(D41,sales!C:C,0)),"없음")} -> 없음 | P41: {=IFERROR(INDEX(sales!E:E,MATCH(D41,sales!C:C,0)),"없음")} -> 없음
A42: 42 | B42: Yejin Heo | C42: 허예진 | D42: yejin.heo@stryker.com | E42: Sales Representative, NV | F42: Sales and Marketing Job Family Group | G42: Direct Sales | H42: {=IFERROR(INDEX(Lease_List!D:D,MATCH(All_User!D42,Lease_List!H:H,0)),"없음")} -> 없음 | I42: 5CD32081ZB | K42: {=IFERROR(INDEX(Ipad_List!C:C,MATCH(All_User!D42,Ipad_List!J:J,0)),"없음")} -> DYQP729JPM | L42: {=IFERROR(INDEX(TeamsNumber!B:B,MATCH(All_User!D42,TeamsNumber!D:D,0)),"없음")} -> tel:+82234517643 | M42: {=IFERROR(INDEX(Printer!D:D,MATCH(All_User!D42,Printer!G:G,0)),"없음")} -> 없음 | N42: {=IFERROR(INDEX(Monitor!A:A,MATCH(D42,Monitor!D:D,0)),"없음")} -> 없음 | O42: {=IFERROR(INDEX(sales!D:D,MATCH(D42,sales!C:C,0)),"없음")} -> NV | P42: {=IFERROR(INDEX(sales!E:E,MATCH(D42,sales!C:C,0)),"없음")} -> NV | Q42: {=IFERROR(INDEX(sales!C:C,MATCH(D42,sales!C:C,0)),"list없음")} -> yejin.heo@stryker.com
A43: 43 | B43: Ashley Hong | C43: 홍윤경 | D43: ashley.hong@stryker.com | E43: Mako Product Specialist | F43: Sales and Marketing Job Family Group | G43: Medical Education | H43: {=IFERROR(INDEX(Lease_List!D:D,MATCH(All_User!D43,Lease_List!H:H,0)),"없음")} -> 5CD4232BFV | I43: 없음 | K43: {=IFERROR(INDEX(Ipad_List!C:C,MATCH(All_User!D43,Ipad_List!J:J,0)),"없음")} -> J99N6MMPMT | L43: {=IFERROR(INDEX(TeamsNumber!B:B,MATCH(All_User!D43,TeamsNumber!D:D,0)),"없음")} -> tel:+82234517581 | M43: {=IFERROR(INDEX(Printer!D:D,MATCH(All_User!D43,Printer!H:H,0)),"없음")} -> 없음 | N43: {=IFERROR(INDEX(Monitor!A:A,MATCH(D43,Monitor!D:D,0)),"없음")} -> 없음 | O43: {=IFERROR(INDEX(sales!D:D,MATCH(D43,sales!C:C,0)),"없음")} -> Mako | P43: {=IFERROR(INDEX(sales!E:E,MATCH(D43,sales!C:C,0)),"없음")} -> MPS | Q43: {=IFERROR(INDEX(sales!C:C,MATCH(D43,sales!C:C,0)),"list없음")} -> ashley.hong@stryker.com
A44: 44 | B44: Seo Yeong Hong | C44: 홍서영 | D44: seoyeong.hong@stryker.com | E44: Operations Specialist, Medical | F44: Supply Chain Job Family Group | G44: Logistics | H44: {=IFERROR(INDEX(Lease_List!D:D,MATCH(All_User!D44,Lease_List!H:H,0)),"없음")} -> 5CD4305D8H | I44: 없음 | K44: {=IFERROR(INDEX(Ipad_List!C:C,MATCH(All_User!D44,Ipad_List!J:J,0)),"없음")} -> 없음 | L44: {=IFERROR(INDEX(TeamsNumber!B:B,MATCH(All_User!D44,TeamsNumber!D:D,0)),"없음")} -> tel:+82234517630 | M44: {=IFERROR(INDEX(Printer!D:D,MATCH(All_User!D44,Printer!H:H,0)),"없음")} -> 없음 | N44: {=IFERROR(INDEX(Monitor!A:A,MATCH(D44,Monitor!D:D,0)),"없음")} -> 없음 | O44: {=IFERROR(INDEX(sales!D:D,MATCH(D44,sales!C:C,0)),"없음")} -> 없음 | P44: {=IFERROR(INDEX(sales!E:E,MATCH(D44,sales!C:C,0)),"없음")} -> 없음
...

Sheet Lease_List
A1: Model | B1: 종류 | C1: SNOW Tag | D1: S/N | E1: lease Date | F1: BU | G1: User | H1: email | I1: Additional Information
A2: HP Elitebook 640 G10 | B2: Laptop | D2: 5CD3469HCY | E2: 40931 | F2: IT | G2: STOCK | I2: 액정파손 수리 완료 / choi kyu(고장)
A3: HP Elitebook 640 G10 | B3: Laptop | D3: 5CD3469HD2 | E3: 40931 | F3: 지평 | G3: Kunji Yun | H3: jpcustoms.skl@stryker.com | J3: {=IFERROR(INDEX(All_User!D:D,MATCH(D3,All_User!H:H,0)),"없음")} -> jpcustoms.skl@stryker.com
A4: HP Elitebook 640 G10 | B4: Laptop | D4: 5CD3469HCX | E4: 40931 | F4: Medsurg | G4: Theo Hwang | H4: theo.hwang@stryker.com | J4: {=IFERROR(INDEX(All_User!D:D,MATCH(D4,All_User!H:H,0)),"없음")} -> theo.hwang@stryker.com
A5: HP Elitebook 640 G10 | B5: Laptop | D5: 5CD3469HCZ | E5: 40931 | F5: IT | G5: kale.lee | H5: kale.lee@stryker.com | J5: {=IFERROR(INDEX(All_User!D:D,MATCH(D5,All_User!H:H,0)),"없음")} -> kale.lee@stryker.com
A6: HP Elitebook 640 G10 | B6: Laptop | D6: 5CD3469HD0 | E6: 40931 | F6: NV | G6: Sophie Bae | H6: sophie.bae@stryker.com | J6: {=IFERROR(INDEX(All_User!D:D,MATCH(D6,All_User!H:H,0)),"없음")} -> sophie.bae@stryker.com
A7: HP Elitebook 640 G10 | B7: Laptop | D7: 5CD3469HD1 | E7: 40931 | F7: Mako | G7: Nathan Lee | H7: nathan.lee@stryker.com | J7: {=IFERROR(INDEX(All_User!D:D,MATCH(D7,All_User!H:H,0)),"없음")} -> nathan.lee@stryker.com
A8: HP Elitebook 640 G10 | B8: Laptop | D8: 5CD3469HD3 | E8: 40931 | F8: Finance | G8: Sungyi Jeon | H8: sungyi.jeon@stryker.com | J8: {=IFERROR(INDEX(All_User!D:D,MATCH(D8,All_User!H:H,0)),"없음")} -> sungyi.jeon@stryker.com
A9: HP Elitebook 640 G10 | B9: Laptop | D9: 5CD3469HD4 | E9: 40931 | F9: Finance | G9: Freddy Park | H9: freddy.park@stryker.com | J9: {=IFERROR(INDEX(All_User!D:D,MATCH(D9,All_User!H:H,0)),"없음")} -> freddy.park@stryker.com
A10: HP Elitebook 640 G10 | B10: Laptop | D10: 5CD3469HD5 | E10: 40931 | F10: Mako | G10: Jackson park | H10: jackson.park@stryker.com | J10: {=IFERROR(INDEX(All_User!D:D,MATCH(D10,All_User!H:H,0)),"없음")} -> jackson.park@stryker.com
A11: HP Elitebook 640 G10 | B11: Laptop | D11: 5CD3469HD6 | E11: 40931 | F11: Mako | G11: Bruce Cha | H11: Bruce.Cha@stryker.com | J11: {=IFERROR(INDEX(All_User!D:D,MATCH(D11,All_User!H:H,0)),"없음")} -> Bruce.Cha@stryker.com
A12: HP Elitebook 640 G10 | B12: Laptop | D12: 5CD3469HD7 | E12: 40931 | F12: RA&QA | G12: Chloe Lee | H12: chloe.lee@stryker.com | J12: {=IFERROR(INDEX(All_User!D:D,MATCH(D12,All_User!H:H,0)),"없음")} -> chloe.lee@stryker.com
A13: HP Elitebook 640 G10 | B13: Laptop | D13: 5CD3469HD8 | E13: 40931 | F13: Finance | G13: jenna.yoo | H13: jenna.yoo@stryker.com | J13: {=IFERROR(INDEX(All_User!D:D,MATCH(D13,All_User!H:H,0)),"없음")} -> jenna.yoo@stryker.com
A14: HP Elitebook 640 G10 | B14: Laptop | D14: 5CD3469HD9 | E14: 40931 | F14: Mako | G14: david.oh | H14: david.oh@stryker.com | J14: {=IFERROR(INDEX(All_User!D:D,MATCH(D14,All_User!H:H,0)),"없음")} -> david.oh@stryker.com
... A20: HP Elitebook 640 G10 | B20: Laptop | D20: 5CD3469HDJ | E20: 40931 | F20: CA | G20: Songmin Kim | H20: songmin.kim@stryker.com | J20: {=IFERROR(INDEX(All_User!D:D,MATCH(D20,All_User!H:H,0)),"없음")} -> songmin.kim@stryker.com
A21: HP Elitebook 640 G10 | B21: Laptop | C21: 430530 | D21: 5CD3469HDK | E21: 40931 | F21: Yongma | G21: order | H21: yongma01(깡통) | J21: {=IFERROR(INDEX(All_User!D:D,MATCH(D21,All_User!H:H,0)),"없음")} -> yongma01(깡통)
A22: HP Elitebook 640 G10 | B22: Laptop | C22: 445031 | D22: 5CD3469HDL | E22: 40931 | F22: IT | G22: STOCK | I22: 블루스크린 PC 반납
A23: HP Elitebook 640 G10 | B23: Laptop | D23: 5CD3469HDM | E23: 40931 | F23: HR | G23: Hansol Shin | H23: hansol.shin@stryker.com | J23: {=IFERROR(INDEX(All_User!D:D,MATCH(D23,All_User!H:H,0)),"없음")} -> hansol.shin@stryker.com
A24: HP Elitebook 640 G10 | B24: Laptop | D24: 5CD3469HDN | E24: 40931 | F24: Planning | G24: Chloe Baek | H24: chloe.baek@stryker.com | J24: {=IFERROR(INDEX(All_User!D:D,MATCH(D24,All_User!H:H,0)),"없음")} -> chloe.baek@stryker.com
A25: HP Elitebook 640 G10 | B25: Laptop | D25: 5CD3469HDP | E25: 40931 | F25: 도원 | G25: Financeadmin4.SKL | H25: financeadmin4.skl@stryker.com | J25: {=IFERROR(INDEX(All_User!D:D,MATCH(D25,All_User!H:H,0)),"없음")} -> financeadmin4.skl@stryker.com
A26: HP Elitebook 640 G10 | B26: Laptop | D26: 5CD3469HDQ | E26: 40931 | F26: Planning | G26: Cindy Jeon | H26: cindy.jeon@stryker.com | J26: {=IFERROR(INDEX(All_User!D:D,MATCH(D26,All_User!H:H,0)),"없음")} -> cindy.jeon@stryker.com
A27: HP Elitebook 640 G10 | B27: Laptop | D27: 5CD3469HDR | E27: 40931 | F27: RA&QA | G27: Irene Jun | H27: irene.jun@stryker.com | J27: {=IFERROR(INDEX(All_User!D:D,MATCH(D27,All_User!H:H,0)),"없음")} -> irene.jun@stryker.com
A28: HP Elitebook 640 G10 | B28: Laptop | D28: 5CD3469HDS | E28: 40931 | F28: 김포 | G28: wondae.koh | H28: wondae.ko@stryker.com | J28: {=IFERROR(INDEX(All_User!D:D,MATCH(D28,All_User!H:H,0)),"없음")} -> wondae.ko@stryker.com
A29: HP Elitebook 640 G10 | B29: Laptop | D29: 5CD3469HDT | E29: 40931 | F29: Knee | G29: Jenny Jung | H29: jenny.jung@stryker.com | J29: {=IFERROR(INDEX(All_User!D:D,MATCH(D29,All_User!H:H,0)),"없음")} -> jenny.jung@stryker.com
A30: HP Elitebook 640 G10 | B30: Laptop | D30: 5CD3469HDV | E30: 40931 | F30: RAQA | G30: Ahyoung Kim | H30: ahyoung.kim@stryker.com | J30: {=IFERROR(INDEX(All_User!D:D,MATCH(D30,All_User!H:H,0)),"없음")} -> ahyoung.kim@stryker.com
A31: HP Elitebook 640 G10 | B31: Laptop | D31: 5CD3469HDG | E31: 40931 | F31: Yongma | G31: CIS | H31: yongma05(깡통) | J31: {=IFERROR(INDEX(All_User!D:D,MATCH(D31,All_User!H:H,0)),"없음")} -> yongma05(깡통)
A32: HP Elitebook 640 G10 | B32: Laptop | D32: 5CD409908H | E32: 04/22/24 | F32: IT | G32: STOCK.
A33: HP Elitebook 640 G10 | B33: Laptop | D33: 5CD409908K | E33: 04/22/24 | F33: HR | G33: Yoori Kim | H33: yoori.kim@stryker.com | J33: {=IFERROR(INDEX(All_User!D:D,MATCH(D33,All_User!H:H,0)),"없음")} -> yoori.kim@stryker.com
A34: HP Elitebook 640 G10 | B34: Laptop | D34: 5CD409908M | E34: 04/22/24 | F34: NV | G34: Sue Kim | H34: Sue.Kim@stryker.com | J34: {=IFERROR(INDEX(All_User!D:D,MATCH(D34,All_User!H:H,0)),"없음")} -> Sue.Kim@stryker.com
A35: HP Elitebook 640 G10 | B35: Laptop | D35: 5CD409908J | E35: 04/22/24 | F35: Implants | G35: Suhyun Kim | H35: Suhyun.Kim@stryker.com | J35: {=IFERROR(INDEX(All_User!D:D,MATCH(D35,All_User!H:H,0)),"없음")} -> Suhyun.Kim@stryker.com
A36: HP Elitebook 640 G10 | B36: Laptop | D36: 5CD409908L | E36: 04/22/24 | F36: NV | G36: Henry Kim | H36: henry.kim1@stryker.com | J36: {=IFERROR(INDEX(All_User!D:D,MATCH(D36,All_User!H:H,0)),"없음")} -> henry.kim1@stryker.com
A37: HP Elitebook 640 G10 | B37: Laptop | D37: 5CD409908N | E37: 04/22/24 | F37: IT | G37: Kmultiuser | H37: kmultiuser@stryker.com
A38: HP Elitebook 640 G10 | B38: Laptop | D38: 5CD4145N3F | E38: 38407 | F38: 김포 | G38: Demoadmin.ym | H38: demoadmin.ym@stryker.com | J38: {=IFERROR(INDEX(All_User!D:D,MATCH(D38,All_User!H:H,0)),"없음")} -> demoadmin.ym@stryker.com
A39: HP Elitebook 640 G10 | B39: Laptop | D39: 5CD4145N3M | E39: 38407 | F39: IT | G39: STOCK | I39: 키보드 교체(한글 스티커)
A40: HP Elitebook 640 G10 | B40: Laptop | D40: 5CD4145N3Q | E40: 38407 | F40: IT | G40: STOCK | I40: Bitlocker Error (KB00216607 참고) KB00216607 에러 발생 > 조치 카탈로그 KB13320 또한 에러 발생
A41: HP Elitebook 640 G10 | B41: Laptop | C41: 435615 | D41: 5CD4145N3G | E41: 38407 | F41: 도원 | G41: Financeadmin3.SKL | H41: Financeadmin3.SKL@stryker.com | J41: {=IFERROR(INDEX(All_User!D:D,MATCH(D41,All_User!H:H,0)),"없음")} -> Financeadmin3.SKL@stryker.com
A42: HP Elitebook 640 G10 | B42: Laptop | D42: 5CD4145N3S | E42: 38407 | F42: Finance | G42: jay.moon | H42: jay.moon@stryker.com | J42: {=IFERROR(INDEX(All_User!D:D,MATCH(D42,All_User!H:H,0)),"없음")} -> jay.moon@stryker.com
A43: HP Elitebook 640 G10 | B43: Laptop | D43: 5CD4145N3N | E43: 38407 | F43: CS | G43: Hyeran Ahn | H43: hyeran.an@stryker.com | J43: {=IFERROR(INDEX(All_User!D:D,MATCH(D43,All_User!H:H,0)),"없음")} -> hyeran.an@stryker.com
A44: HP Elitebook 640 G10 | B44: Laptop | D44: 5CD4145N3P | E44: 38407 | F44: Legal | G44: Greg Kim | H44: greg.kim@stryker.com | J44: {=IFERROR(INDEX(All_User!D:D,MATCH(D44,All_User!H:H,0)),"없음")} -> greg.kim@stryker.com
A45: HP Elitebook 640 G10 | B45: Laptop | D45: 5CD4145N3K | E45: 38407 | F45: Mako | G45: Mason Kim | H45: mason.kim1@stryker.com | J45: {=IFERROR(INDEX(All_User!D:D,MATCH(D45,All_User!H:H,0)),"없음")} -> mason.kim1@stryker.com
...

Sheet TeamsNumber
A1: Extension | B1: LineURI | C1: Number formated for Country | D1: email | E1: Business Title | F1: ID
A2: 7500 | B2: tel:+82234517500 | C2: =+82 2 3451 7500 | D2: dahye.jeong@stryker.com | E2: #N/A | F2: 대표번호 할당 불가
A3: 7501 | B3: tel:+82234517501 | C3: =+82 2 3451 7501 | D3: sungyi.jeon@stryker.com | E3: #N/A
A4: 7502 | B4: tel:+82234517502 | C4: =+82 2 3451 7502 | D4: annie.lee@stryker.com | E4: #N/A
A5: 7503 | B5: tel:+82234517503 | C5: =+82 2 3451 7503 | D5: hr.sklasem@stryker.com | E5: #N/A
A6: 7504 | B6: tel:+82234517504 | C6: =+82 2 3451 7504 | D6: leadership.sklasem@stryker.com | E6: #N/A
A7: 7505 | B7: tel:+82234517505 | C7: =+82 2 3451 7505 | D7: mahwah.sklasem@stryker.com | E7: #N/A
A8: 7506 | B8: tel:+82234517506 | C8: =+82 2 3451 7506 | D8: mako.sklasem@stryker.com | E8: #N/A
A9: 7507 | B9: tel:+82234517507 | C9: =+82 2 3451 7507 | D9: nv.sklasem@stryker.com | E9: #N/A
A10: 7508 | B10: tel:+82234517508 | C10: =+82 2 3451 7508 | D10: raqa.sklasem@stryker.com | E10: #N/A
A11: 7509 | B11: tel:+82234517509 | C11: =+82 2 3451 7509 | D11: target.sklasem@stryker.com | E11: #N/A
A12: 7510 | B12: tel:+82234517510 | C12: =+82 2 3451 7510 | D12: drsouthkorea.teams@stryker.com | E12: #N/A
A13: 7511 | B13: tel:+82234517511 | C13: =+82 2 3451 7511 | D13: jiwon.yoo@stryker.com | E13: #N/A
A14: 7512 | B14: tel:+82234517512 | C14: =+82 2 3451 7512 | D14: andrew.ahn@stryker.com | E14: #N/A
... A19: 7517 | B19: tel:+82234517517 | C19: =+82 2 3451 7517 | D19: mason.choi@stryker.com | E19: #N/A
A20: 7518 | B20: tel:+82234517518 | C20: =+82 2 3451 7518 | D20: kita.ym@stryker.com | E20: #N/A | F20: 용마 키트 Admin
A21: 7519 | B21: tel:+82234517519 | C21: =+82 2 3451 7519 | D21: chloe.baek@stryker.com | E21: #N/A
A22: 7520 | B22: tel:+82234517520 | C22: =+82 2 3451 7520 | D22: kevin.shim@stryker.com | E22: #N/A
A23: 7521 | B23: tel:+82234517521 | C23: =+82 2 3451 7521 | D23: chloe.lee@stryker.com | E23: #N/A
A24: 7522 | B24: tel:+82234517522 | C24: =+82 2 3451 7522 | D24: chris.shin@stryker.com | E24: #N/A
A25: 7523 | B25: tel:+82234517523 | C25: =+82 2 3451 7523 | D25: sally.choi@stryker.com | E25: #N/A
A26: 7524 | B26: tel:+82234517524 | C26: =+82 2 3451 7524 | D26: leslie.kim@stryker.com | E26: #N/A
A27: 7525 | B27: tel:+82234517525 | C27: =+82 2 3451 7525 | D27: claire.choi@stryker.com | E27: #N/A
A28: 7526 | B28: tel:+82234517526 | C28: =+82 2 3451 7526 | D28: clare.yang@stryker.com | E28: #N/A
A29: 7527 | B29: tel:+82234517527 | C29: =+82 2 3451 7527 | D29: chan.jeon@stryker.com | E29: #N/A
A30: 7528 | B30: tel:+82234517528 | C30: =+82 2 3451 7528 | D30: dana.shin@stryker.com | E30: #N/A
A31: 7529 | B31: tel:+82234517529 | C31: =+82 2 3451 7529 | D31: soyoun.kim@stryker.com | E31: #N/A
A32: 7530 | B32: tel:+82234517530 | C32: =+82 2 3451 7530 | D32: danny.kim@stryker.com | E32: #N/A
... A35: 7533 | B35: tel:+82234517533 | C35: =+82 2 3451 7533 | D35: david.yang@stryker.com | E35: #N/A
A36: 7534 | B36: tel:+82234517534 | C36: =+82 2 3451 7534 | E36: Shoulder KLT 사용하던 것
A37: 7535 | B37: tel:+82234517535 | C37: =+82 2 3451 7535 | D37: ethan.jang@stryker.com | E37: #N/A
A38: 7536 | B38: tel:+82234517536 | C38: =+82 2 3451 7536 | D38: dongkyu.kim@stryker.com | E38: #N/A
A39: 7537 | B39: tel:+82234517537 | C39: =+82 2 3451 7537 | D39: jisoo.yang@stryker.com | E39: #N/A
A40: 7538 | B40: tel:+82234517538 | C40: =+82 2 3451 7538 | E40: Elin KIM / knee 사용
A41: 7539 | B41: tel:+82234517539 | C41: =+82 2 3451 7539 | E41: Legal KLT 사용하던 것
A42: 7540 | B42: tel:+82234517540 | C42: =+82 2 3451 7540 | D42: yoori.kim@stryker.com | E42: #N/A
A43: 7541 | B43: tel:+82234517541 | C43: =+82 2 3451 7541 | D43: hansol.shin@stryker.com | E43: #N/A
A44: 7542 | B44: tel:+82234517542 | C44: =+82 2 3451 7542 | D44: ethan.song@stryker.com | E44: #N/A
A45: 7543 | B45: tel:+82234517543 | C45: =+82 2 3451 7543 | D45: chloe.kang@stryker.com | E45: #N/A
A46: 7544 | B46: tel:+82234517544 | C46: =+82 2 3451 7544 | D46: freddy.park@stryker.com | E46: #N/A
...

Sheet Ipad_List
A1: 개수 | B1: Model | C1: S/N | D1: Date | E1: 전화 번호 | F1: 애플펜슬 2세대 | G1: BU | H1: Role | I1: User | J1: email | K1: Additional Information | L1: 해지유무 | M1: 참고
A3: 1 | B3: iPAD_Pro_12.9_Gen3_64 | C3: DLXZX04QKC5Q | D3: 44121 | E3: 010-4352-6949 | F3: 1 | G3: IT | H3: IT | K3: Johnny Choi 반납 / 펜슬 미반납 | L3: 해지완료 | M3: 2025.03.19 재약정 / 위약금 발생
A4: 2 | B4: iPAD_Air_Gen5_256 | C4: KG27H3Q1J1 | D4: 44711 | E4: 010-6681-6949 | F4: 1 | G4: Knee | H4: KLT | I4: Jason Han | J4: jason.han@stryker.com | M4: 2025.03.19 재약정
A5: 3 | B5: iPAD_Pro_12.9_Gen3_64 | C5: DLXCC00MKC43 | D5: 44121 | E5: 010-9984-6182 | F5: 1 | G5: GM | H5: KLT | I5: Kevin Shim | J5: kevin.shim@stryker.com
A6: 4 | B6: iPAD_Pro_12.9_Gen3_64 | C6: DLXCC0M0KC43 | D6: 44121 | E6: 해지 완료 | G6: Finance | H6: KLT | I6: Heesun Cho | J6: heesun.cho@stryker.com | L6: 해지완료
A7: 5 | B7: IPADP4_11-128 | C7: FQ29PC2NKJ | D7: 44995 | E7: 010-6878-0164 | F7: 1 | G7: Spare | H7: KLT | I7: TESTing by Jun
A8: 6 | B8: IPADP4_11-128 | C8: K9J441WF9W | D8: 44995 | E8: 010-6878-0172 | F8: 1 | G8: Mako | H8: MPS | I8: Sujin park | J8: sujin.park@stryker.com
A9: 7 | B9: IPADP4_11-128 | C9: J1XWPW66YY | D9: 44995 | E9: 해지 완료 | G9: IT | H9: IT | I9: Kale Lee | J9: kale.lee@stryker.com | L9: 해지완료
A10: 8 | B10: IPADP4_11-128 | C10: CK7JHKH443 | D10: 44995 | E10: 010-6878-0256 | G10: IT | H10: IT | I10: stock | M10: 수리완료 오른쪽 라인 터치 안됨
A11: 9 | B11: IPADP4_11-128 | C11: G9YWDFP14H | D11: 44995 | E11: 010-6878-0276 | G11: Operation | H11: KLT | I11: Minsu Yi | J11: minsu.yi@stryker.com
A12: 10 | B12: IPADP4_11-128 | C12: HL7Q0T6MHW | D12: 44995 | E12: 010-6878-0299 | F12: 1 | G12: Mako | H12: MPS | I12: Vincent Bea | J12: vincent.bae@stryker.com
A13: 11 | B13: IPADP4_11-128 | C13: J2Y7TQ0Y79 | D13: 44995 | E13: 010-6878-0340 | G13: IT | H13: IT | I13: stock | K13: Tony Kang 쓰던거 IPAD부족할때 사용 | L13: 해지완료
A14: 12 | B14: IPADP4_11-128 | C14: MP2C9F46FN | D14: 45079 | E14: 010-6878-0446 | F14: 1 | G14: Implants | H14: KLT | I14: Peter Oh | J14: peter.oh@stryker.com
A15: 13 | B15: IPADP4_11-128 | C15: J9157FQXYM | D15: 45079 | E15: 010-6878-0449 | F15: 1 | G15: Implants | H15: Sales | I15: Genie Kim | J15: genie.kim@stryker.com | M15: {=IFERROR(INDEX(sales!C:C,MATCH(J15,sales!C:C,0)),"LIST없음")} -> genie.kim@stryker.com
A16: 14 | B16: IPADP4_11-128 | C16: D50QVTWX76 | D16: 45079 | E16: 010-6878-0457 | G16: Medsurg | H16: MKT | I16: Bella Yoon | J16: bella.yoon@stryker.com | M16: {=IFERROR(INDEX(Printer!H:H,MATCH(J16,Printer!H:H,0)),"PRINTER LIST없음")} -> PRINTER LIST없음
A17: 15 | B17: IPADP4_11-128 | C17: GXDWV9GT62 | D17: 45079 | E17: 010-6878-0458 | F17: 1 | G17: Mako | H17: Sales | I17: david oh | J17: david.oh@stryker.com | M17: {=IFERROR(INDEX(sales!C:C,MATCH(J17,sales!C:C,0)),"LIST없음")} -> david.oh@stryker.com
A18: 16 | B18: IPADP4_11-128 | C18: G09WDG49T4 | D18: 45079 | E18: 010-6878-0459 | G18: Mako | H18: MPS | I18: Sol jung | J18: sol.jung@stryker.com
A19: 17 | B19: IPADP4_11-128 | C19: M9CN2VYJ46 | D19: 45079 | E19: 010-6878-0463 | F19: 1 | G19: Medical | H19: Sales | I19: Michelle Park | J19: michelle.park@stryker.com | M19: {=IFERROR(INDEX(sales!C:C,MATCH(J19,sales!C:C,0)),"LIST없음")} -> michelle.park@stryker.com
A20: 18 | B20: IPADP4_11-128 | C20: C14X1226DV | D20: 45079 | E20: 010-6878-0464 | G20: HR | H20: KLT | I20: Yoori Kim | J20: yoori.kim@stryker.com
A21: 19 | B21: IPADP4_11-128 | C21: TRW5JJG7JP | D21: 45079 | E21: 010-6878-0465 | G21: RAQA | H21: KLT | I21: Leslie Kim | J21: Leslie.kim@stryker.com
A22: 20 | B22: IPADP4_11-128 | C22: J6YXV33LDP | D22: 45079 | E22: 010-6878-0359 | G22: Mako | H22: MPS | I22: Jade Jung | J22: jade.jung@stryker.com
A23: 21 | B23: IPADP4_11-128 | C23: KJ44CP93XQ | D23: 45079 | E23: 010-6878-0381 | F23: 1 | G23: NV | H23: Sales | I23: Gregory Seo | J23: Gregory.Seo@stryker.com | M23: {=IFERROR(INDEX(Printer!H:H,MATCH(J23,Printer!H:H,0)),"PRINTER LIST없음")} -> Gregory.Seo@stryker.com
A24: 22 | B24: IPADP4_11-128 | C24: HW21HF1YCH | D24: 45079 | E24: 010-6878-0382 | G24: MA | H24: KLT | I24: JH Ji | J24: jh.ji@stryker.com | L24: 해지완료
A25: 23 | B25: IPADP4_11-128 | C25: KXDGGF9C90 | D25: 45079 | E25: 010-6878-0389 | F25: 1 | G25: Medusrg | H25: Sales | I25: Joy Lee | J25: joy.lee@stryker.com | M25: {=IFERROR(INDEX(sales!C:C,MATCH(J25,sales!C:C,0)),"LIST없음")} -> joy.lee@stryker.com
A26: 24 | B26: IPADP4_11-128 | C26: HC0FP2JHG7 | D26: 45079 | E26: 010-6878-0392 | F26: 1 | G26: Medsurg | H26: Sales | I26: David Kim | J26: david.kim3@stryker.com | L26: 해지완료 | M26: {=IFERROR(INDEX(sales!C:C,MATCH(J26,sales!C:C,0)),"LIST없음")} -> david.kim3@stryker.com
A27: 25 | B27: IPADP4_11-128 | C27: DG3XL2W5VX | D27: 45079 | E27: 010-6878-0394 | F27: 1 | G27: Knee | H27: MKT | I27: Jenny Jung | J27: jenny.jung@stryker.com | L27: 해지완료 | M27: {=IFERROR(INDEX(Printer!H:H,MATCH(J27,Printer!H:H,0)),"PRINTER LIST없음")} -> PRINTER LIST없음
A28: 26 | B28: IPADP4_11-128 | C28: C19HH7PP2V | D28: 45079 | E28: 010-6878-0395 | F28: 1 | G28: Mako | H28: MPS | I28: Seo Hyun Jung | J28: seohyun.jung@stryker.com
A29: 27 | B29: IPADP4_11-128 | C29: KVKXR477HX | D29: 45079 | E29: 010-6878-0398 | F29: 1 | G29: Mako | H29: MPS | I29: Shawn Kim | J29: shawn.kim@stryker.com | K29: william chai 사용한것
A30: 28 | B30: IPADP4_11-128 | C30: JN14143DQC | D30: 45079 | E30: 010-6878-0437 | F30: 1 | G30: Medsurg | H30: Sales | I30: Henry Lee | J30: henry.lee@stryker.com | M30: {=IFERROR(INDEX(sales!C:C,MATCH(J30,sales!C:C,0)),"LIST없음")} -> henry.lee@stryker.com
A31: 29 | B31: IPADP4_11-128 | C31: C2QFHGVW92 | D31: 45079 | E31: 010-6878-0443 | F31: 1 | G31: NV | H31: Sales | I31: Mi Na Song | J31: mina.song@stryker.com | M31: {=IFERROR(INDEX(sales!C:C,MATCH(J31,sales!C:C,0)),"LIST없음")} -> mina.song@stryker.com
A32: 30 | B32: IPADP4_11-128 | C32: DP77MWKXNR | D32: 45131 | E32: 010-6878-0534 | G32: TS | H32: TS | I32: Owen Park | J32: owen.park@stryker.com | M32: {=IFERROR(INDEX(Printer!H:H,MATCH(J32,Printer!H:H,0)),"PRINTER LIST없음")} -> PRINTER LIST없음
A33: 31 | B33: IPADP4_11-128 | C33: GWR3CYT2GJ | D33: 45131 | E33: 010-6878-0536 | F33: 1 | G33: Mako | H33: MKT | I33: Rosie Lee | J33: rosie.lee@stryker.com | L33: 해지완료 | M33: {=IFERROR(INDEX(Printer!H:H,MATCH(J33,Printer!H:H,0)),"PRINTER LIST없음")} -> PRINTER LIST없음
A34: 32 | B34: IPADP4_11-128 | C34: HYC714DK25 | D34: 45131 | E34: 010-6878-0541 | G34: Implants | H34: MKT | I34: Sarah Youn | J34: sarah.youn@stryker.com | L34: 해지완료 | M34: {=IFERROR(INDEX(Printer!H:H,MATCH(J34,Printer!H:H,0)),"PRINTER LIST없음")} -> PRINTER LIST없음
A35: 33 | B35: IPADP4_11-128 | C35: L4J4KPXGPN | D35: 45131 | E35: 010-6878-0548 | G35: IT | H35: IT | I35: stock | J35: - | K35: 김자영마지막 : Legal / KLT IPAD부족할때 사용 | L35: 해지완료
A36: 34 | B36: IPADP4_11-128 | C36: L2717D33PM | D36: 45131 | E36: 010-6878-0562 | F36: 1 | G36: Mako | H36: MPS | I36: Lucia Park | J36: lucia.park@stryker.com
A37: 35 | B37: IPADP4_11-128 | C37: CXVPVQXG09 | D37: 45131 | E37: 010-6878-0481 | F37: 1 | G37: Knee | H37: Sales | I37: Leo Han | J37: leo.han@stryker.com | M37: {=IFERROR(INDEX(sales!C:C,MATCH(J37,sales!C:C,0)),"LIST없음")} -> leo.han@stryker.com
A38: 36 | B38: IPADP4_11-128 | C38: P7Q3X0HYFW | D38: 45131 | E38: 010-6878-0483 | F38: 1 | G38: Knee | H38: Sales | I38: Jayden Kim | J38: jayden.kim@stryker.com | M38: {=IFERROR(INDEX(sales!C:C,MATCH(J38,sales!C:C,0)),"LIST없음")} -> jayden.kim@stryker.com
A39: 37 | B39: IPADP4_11-128 | C39: CQ0MQK66GM | D39: 45131 | E39: 010-6878-0485 | F39: 1 | G39: Knee | H39: Sales | I39: Claire Choi | J39: claire.choi@stryker.com | M39: {=IFERROR(INDEX(sales!C:C,MATCH(J39,sales!C:C,0)),"LIST없음")} -> claire.choi@stryker.com
A40: 38 | B40: IPADP4_11-128 | C40: XCYDTQ4H1F | D40: 45131 | E40: 010-6878-0487 | F40: 1 | G40: Knee | H40: Sales | I40: Suhwan Jung | J40: suhwan.jung@stryker.com | L40: 해지완료 | M40: {=IFERROR(INDEX(sales!C:C,MATCH(J40,sales!C:C,0)),"LIST없음")} -> suhwan.jung@stryker.com
A41: 39 | B41: IPADP4_11-128 | C41: LR4DPX93T4 | D41: 45131 | E41: 010-6878-0490 | F41: 1 | G41: Knee | H41: Sales | I41: Chris Shin | J41: chris.shin@stryker.com | M41: {=IFERROR(INDEX(sales!C:C,MATCH(J41,sales!C:C,0)),"LIST없음")} -> chris.shin@stryker.com
...

Sheet Printer
B1: Model | C1: date | D1: Additional Information 2 | E1: User | F1: BU | G1: ROLE | H1: email | I1: 카트리지 사용 내역
A2: 1 | B2: 삼성복합기 | D2: SL-C486FW | E2: OA Room | F2: 아셈타워 | G2: oa
A3: 2 | B3: 삼성복합기 | D3: 2차 조사 정보 없음 | E3: Jason Kim | F3: Implants | G3: Sales | H3: jason.kim1@stryker.com | J3: {=IFERROR(INDEX(All_User!D:D,MATCH(H3,All_User!D:D,0)),"없음")} -> jason.kim1@stryker.com | L3: {=IFERROR(INDEX(sales!G:G,MATCH(H3,sales!C:C,0)),"없음")} -> 2차 조사 정보 없음
A4: 3 | B4: SL-C486FW | C4: 45597 | D4: SL-C486FW | E4: Suhyun Kim | F4: Implants | G4: Sales | H4: Suhyun.Kim@stryker.com | J4: {=IFERROR(INDEX(All_User!D:D,MATCH(H4,All_User!D:D,0)),"없음")} -> Suhyun.Kim@stryker.com | L4: {=IFERROR(INDEX(sales!G:G,MATCH(H4,sales!C:C,0)),"없음")} -> SL-C486FW
A5: 4 | D5: 반납 | E5: Genie Kim | F5: Implants | G5: Sales | H5: genie.kim@stryker.com | J5: {=IFERROR(INDEX(All_User!D:D,MATCH(H5,All_User!D:D,0)),"없음")} -> genie.kim@stryker.com | L5: {=IFERROR(INDEX(sales!G:G,MATCH(H5,sales!C:C,0)),"없음")} -> 반납
A6: 5 | B6: SL-C563W | C6: 45108 | D6: SL-C563W | E6: Ayaan Lee | F6: Implants | G6: Sales | H6: ayaan.lee@stryker.com | J6: {=IFERROR(INDEX(All_User!D:D,MATCH(H6,All_User!D:D,0)),"없음")} -> ayaan.lee@stryker.com | L6: {=IFERROR(INDEX(sales!G:G,MATCH(H6,sales!C:C,0)),"없음")} -> SL-C563W
A7: 6 | B7: SL-C563W | C7: 45108 | D7: SL-C563W | E7: Martin Cho | F7: Implants | G7: Sales | H7: martin.cho@stryker.com | I7: SCLT-510Y (1) | J7: {=IFERROR(INDEX(All_User!D:D,MATCH(H7,All_User!D:D,0)),"없음")} -> martin.cho@stryker.com | L7: {=IFERROR(INDEX(sales!G:G,MATCH(H7,sales!C:C,0)),"없음")} -> SL-C563W
A8: 8 | B8: 삼성복합기 | C8: 2023년 9월 4색토너 | D8: SL-C438W | E8: Peter Park | F8: Shoulder | G8: Sales | H8: peter.park@stryker.com | J8: {=IFERROR(INDEX(All_User!D:D,MATCH(H8,All_User!D:D,0)),"없음")} -> peter.park@stryker.com | L8: {=IFERROR(INDEX(sales!G:G,MATCH(H8,sales!C:C,0)),"없음")} -> SL-C438W
A9: 9 | B9: 삼성복합기 | D9: 2차 조사 정보 없음 | E9: Mason Oh | F9: Shoulder | G9: Sales | H9: mason.oh@stryker.com | J9: {=IFERROR(INDEX(All_User!D:D,MATCH(H9,All_User!D:D,0)),"없음")} -> mason.oh@stryker.com | L9: {=IFERROR(INDEX(sales!G:G,MATCH(H9,sales!C:C,0)),"없음")} -> 2차 조사 정보 없음
A10: 10 | D10: SL-C486FW | E10: James Kim | F10: Shoulder | G10: Sales | H10: james.kim@stryker.com | J10: {=IFERROR(INDEX(All_User!D:D,MATCH(H10,All_User!D:D,0)),"없음")} -> james.kim@stryker.com | L10: {=IFERROR(INDEX(sales!G:G,MATCH(H10,sales!C:C,0)),"없음")} -> SL-C486FW
A11: 11 | B11: 삼성복합기 | D11: 확인중 | E11: Jeff Lee | F11: Mako | G11: Sales | H11: Jeff.Lee@stryker.com | J11: {=IFERROR(INDEX(All_User!D:D,MATCH(H11,All_User!D:D,0)),"없음")} -> Jeff.Lee@stryker.com | L11: {=IFERROR(INDEX(sales!G:G,MATCH(H11,sales!C:C,0)),"없음")} -> 확인중
A12: 12 | B12: 삼성복합기 | D12: SL-C483FW | E12: David Yang | F12: Mako | G12: Sales | H12: David.Yang@stryker.com | J12: {=IFERROR(INDEX(All_User!D:D,MATCH(H12,All_User!D:D,0)),"없음")} -> David.Yang@stryker.com | L12: {=IFERROR(INDEX(sales!G:G,MATCH(H12,sales!C:C,0)),"없음")} -> SL-C483FW
A13: 13 | B13: 삼성복합기 | C13: 2023년 12월 4색 토너 | D13: SL-C565W | E13: Justin Kim | F13: Mako | G13: Sales | H13: Justin.Kim@stryker.com | J13: {=IFERROR(INDEX(All_User!D:D,MATCH(H13,All_User!D:D,0)),"없음")} -> Justin.Kim@stryker.com | L13: {=IFERROR(INDEX(sales!G:G,MATCH(H13,sales!C:C,0)),"없음")} -> SL-C565W
A14: 14 | B14: 삼성복합기 | D14: SL-C565FW | E14: Willy Chang | F14: Mako | G14: Sales | H14: Willy.Chang@stryker.com | J14: {=IFERROR(INDEX(All_User!D:D,MATCH(H14,All_User!D:D,0)),"없음")} -> Willy.Chang@stryker.com | L14: {=IFERROR(INDEX(sales!G:G,MATCH(H14,sales!C:C,0)),"없음")} -> SL-C565FW
A15: 15 | B15: 삼성복합기 | D15: SL-C486FW | E15: David Oh | F15: Mako | G15: Sales | H15: david.oh@stryker.com | J15: {=IFERROR(INDEX(All_User!D:D,MATCH(H15,All_User!D:D,0)),"없음")} -> david.oh@stryker.com | L15: {=IFERROR(INDEX(sales!G:G,MATCH(H15,sales!C:C,0)),"없음")} -> SL-C486FW
A16: 16 | B16: 삼성복합기 | D16: 확인중 | E16: GD Ahn | F16: Mako | G16: Sales | H16: gd.ahn@stryker.com | J16: {=IFERROR(INDEX(All_User!D:D,MATCH(H16,All_User!D:D,0)),"없음")} -> gd.ahn@stryker.com | L16: {=IFERROR(INDEX(sales!G:G,MATCH(H16,sales!C:C,0)),"없음")} -> 확인중
A17: 17 | B17: 삼성복합기 | D17: 폐기 | E17: Roy Choi | F17: Mako | G17: Sales | H17: roy.choi@stryker.com | J17: {=IFERROR(INDEX(All_User!D:D,MATCH(H17,All_User!D:D,0)),"없음")} -> roy.choi@stryker.com | L17: {=IFERROR(INDEX(sales!G:G,MATCH(H17,sales!C:C,0)),"없음")} -> 폐기
A18: 18 | B18: SL-C563W | C18: 45261 | D18: SL-C563W | E18: Yeonjoo Kim | F18: Mako | G18: Sales | H18: yeonjoo.kim@stryker.com | J18: {=IFERROR(INDEX(All_User!D:D,MATCH(H18,All_User!D:D,0)),"없음")} -> yeonjoo.kim@stryker.com | L18: {=IFERROR(INDEX(sales!G:G,MATCH(H18,sales!C:C,0)),"없음")} -> SL-C563W
A19: 19 | B19: SL-C563W | C19: 45292 | D19: SL-C563W | E19: Yoonbee Jeong | F19: Mako | G19: Sales | H19: yoonbee.jeong@stryker.com | J19: {=IFERROR(INDEX(All_User!D:D,MATCH(H19,All_User!D:D,0)),"없음")} -> yoonbee.jeong@stryker.com | L19: {=IFERROR(INDEX(sales!G:G,MATCH(H19,sales!C:C,0)),"없음")} -> SL-C563W
A20: 20 | B20: SL-C563W | C20: 45292 | D20: SL-C563W | E20: Leo Han | F20: Mako | G20: Sales | H20: leo.han@stryker.com | J20: {=IFERROR(INDEX(All_User!D:D,MATCH(H20,All_User!D:D,0)),"없음")} -> leo.han@stryker.com | L20: {=IFERROR(INDEX(sales!G:G,MATCH(H20,sales!C:C,0)),"없음")} -> SL-C563W
A21: 21 | B21: SL-C563W | C21: 45292 | D21: SL-C563W | E21: Claire Choi | F21: Mako | G21: Sales | H21: claire.choi@stryker.com | J21: {=IFERROR(INDEX(All_User!D:D,MATCH(H21,All_User!D:D,0)),"없음")} -> claire.choi@stryker.com | L21: {=IFERROR(INDEX(sales!G:G,MATCH(H21,sales!C:C,0)),"없음")} -> SL-C563W
A22: 22 | B22: SL-C563W | C22: 45689 | D22: SL-C563W | E22: Jayden Kim | F22: Mako | G22: Sales | H22: jayden.kim@stryker.com | J22: {=IFERROR(INDEX(All_User!D:D,MATCH(H22,All_User!D:D,0)),"없음")} -> jayden.kim@stryker.com | L22: {=IFERROR(INDEX(sales!G:G,MATCH(H22,sales!C:C,0)),"없음")} -> SL-C563W
A23: 23 | B23: 삼성복합기 | D23: 2차 조사 정보 없음 | E23: JW Yoon | F23: Knee | G23: Sales | H23: jw.yoon@stryker.com | J23: {=IFERROR(INDEX(All_User!D:D,MATCH(H23,All_User!D:D,0)),"없음")} -> jw.yoon@stryker.com | L23: {=IFERROR(INDEX(sales!G:G,MATCH(H23,sales!C:C,0)),"없음")} -> 2차 조사 정보 없음
A24: 24 | B24: 삼성복합기 | D24: SL-C486FW | E24: Jiho Yoo | F24: Knee | G24: Sales | H24: jiho.yoo@stryker.com | J24: {=IFERROR(INDEX(All_User!D:D,MATCH(H24,All_User!D:D,0)),"없음")} -> jiho.yoo@stryker.com | L24: {=IFERROR(INDEX(sales!G:G,MATCH(H24,sales!C:C,0)),"없음")} -> SL-C486FW
A25: 25 | B25: SL-C563W | C25: 45352 | D25: SL-C563W | E25: Louis Kang | F25: Knee | G25: Sales | H25: louis.kang@stryker.com | J25: {=IFERROR(INDEX(All_User!D:D,MATCH(H25,All_User!D:D,0)),"없음")} -> louis.kang@stryker.com | L25: {=IFERROR(INDEX(sales!G:G,MATCH(H25,sales!C:C,0)),"없음")} -> SL-C563W
A26: 26 | B26: 삼성복합기 | C26: 45474 | D26: SL-C563W | E26: Theo Hwang | F26: Knee | G26: Sales | H26: theo.hwang@stryker.com | J26: {=IFERROR(INDEX(All_User!D:D,MATCH(H26,All_User!D:D,0)),"없음")} -> theo.hwang@stryker.com | L26: {=IFERROR(INDEX(sales!G:G,MATCH(H26,sales!C:C,0)),"없음")} -> SL-C563W
A27: 27 | B27: 삼성복합기 | D27: 2차 조사 정보 없음 | E27: Jack Eum | F27: Knee | G27: Sales | H27: jack.eum@stryker.com | J27: {=IFERROR(INDEX(All_User!D:D,MATCH(H27,All_User!D:D,0)),"없음")} -> jack.eum@stryker.com | L27: {=IFERROR(INDEX(sales!G:G,MATCH(H27,sales!C:C,0)),"없음")} -> 2차 조사 정보 없음
